{"uid":"9e26c66a98dc3f03","name":"test_load_pages_with_title[billing-Billing-//h1]","fullName":"tests.performance.test_load_page.TestLoadPage#test_load_pages_with_title","historyId":"41f302fa05c8e6cd0ae2cc6de62b8f2f","time":{"start":1726945030197,"stop":1726945030197,"duration":0},"descriptionHtml":"<h4 style=\"margin: -10px 0 5px;\"><span style=\"margin: 9px 4px 9px 0; cursor: pointer\" class=\"fa fa-files-o\" data-copy=\"test_load_pages_with_title[billing-Billing-//h1]\"></span>test_load_pages_with_title[billing-Billing-//h1]</h4>\n    Collected at <span class=\"label label_status_passed\">2024-09-21 18:54</span><br><br>","status":"broken","statusMessage":"requests.exceptions.HTTPError: 401 Client Error: Unauthorized for url: https://dev.api.darkbot.io/auth/login","statusTrace":"@pytest.fixture(scope=\"class\")\n    def class_create_session():\n        from modules.Utils import prepare_user_session\n>       return prepare_user_session(auth_data=cfg.PREMIUM_USER)\n\nprepare_user_session = <function prepare_user_session at 0x7f726cdf65c0>\n\nconftest.py:160: \n_ _ _ _ _ _ _ _ _ _ _ _ _ _ _ _ _ _ _ _ _ _ _ _ _ _ _ _ _ _ _ _ _ _ _ _ _ _ _ _ \nmodules/Utils.py:56: in prepare_user_session\n    res = AuthApi(auth_data=auth_data)\n        auth_data  = {'password': 'darkbot123', 'token': 'token', 'username': 'premium@darkbot.io'}\nsrc/api/base_api.py:22: in __init__\n    self._login(auth_data)\n        auth_data  = {'password': 'darkbot123', 'token': 'token', 'username': 'premium@darkbot.io'}\n        jwt_token  = None\n        lang       = 'en'\n        self       = <src.api.auth.register_api.AuthApi object at 0x7f7260161820>\nsrc/api/base_api.py:30: in _login\n    raise e\n        auth_data  = {'password': 'darkbot123', 'token': 'token', 'username': 'premium@darkbot.io'}\n        response   = <Response [401]>\n        self       = <src.api.auth.register_api.AuthApi object at 0x7f7260161820>\nsrc/api/base_api.py:27: in _login\n    response.raise_for_status()\n        auth_data  = {'password': 'darkbot123', 'token': 'token', 'username': 'premium@darkbot.io'}\n        response   = <Response [401]>\n        self       = <src.api.auth.register_api.AuthApi object at 0x7f7260161820>\n_ _ _ _ _ _ _ _ _ _ _ _ _ _ _ _ _ _ _ _ _ _ _ _ _ _ _ _ _ _ _ _ _ _ _ _ _ _ _ _ \n\nself = <Response [401]>\n\n    def raise_for_status(self):\n        \"\"\"Raises :class:`HTTPError`, if one occurred.\"\"\"\n    \n        http_error_msg = \"\"\n        if isinstance(self.reason, bytes):\n            # We attempt to decode utf-8 first because some servers\n            # choose to localize their reason strings. If the string\n            # isn't utf-8, we fall back to iso-8859-1 for all other\n            # encodings. (See PR #3538)\n            try:\n                reason = self.reason.decode(\"utf-8\")\n            except UnicodeDecodeError:\n                reason = self.reason.decode(\"iso-8859-1\")\n        else:\n            reason = self.reason\n    \n        if 400 <= self.status_code < 500:\n            http_error_msg = (\n                f\"{self.status_code} Client Error: {reason} for url: {self.url}\"\n            )\n    \n        elif 500 <= self.status_code < 600:\n            http_error_msg = (\n                f\"{self.status_code} Server Error: {reason} for url: {self.url}\"\n            )\n    \n        if http_error_msg:\n>           raise HTTPError(http_error_msg, response=self)\nE           requests.exceptions.HTTPError: 401 Client Error: Unauthorized for url: https://dev.api.darkbot.io/auth/login\n\nhttp_error_msg = '401 Client Error: Unauthorized for url: https://dev.api.darkbot.io/auth/login'\nreason     = 'Unauthorized'\nself       = <Response [401]>\n\n/opt/hostedtoolcache/Python/3.12.6/x64/lib/python3.12/site-packages/requests/models.py:1021: HTTPError","flaky":false,"newFailed":false,"newBroken":false,"newPassed":false,"retriesCount":1,"retriesStatusChange":false,"beforeStages":[{"name":"class_create_session","time":{"start":1726945026559,"stop":1726945027214,"duration":655},"status":"broken","statusMessage":"requests.exceptions.HTTPError: 401 Client Error: Unauthorized for url: https://dev.api.darkbot.io/auth/login\n","statusTrace":"  File \"/opt/hostedtoolcache/Python/3.12.6/x64/lib/python3.12/site-packages/pluggy/_callers.py\", line 167, in _multicall\n    teardown.throw(outcome._exception)\n  File \"/opt/hostedtoolcache/Python/3.12.6/x64/lib/python3.12/site-packages/_pytest/setuponly.py\", line 36, in pytest_fixture_setup\n    return (yield)\n            ^^^^^\n  File \"/opt/hostedtoolcache/Python/3.12.6/x64/lib/python3.12/site-packages/pluggy/_callers.py\", line 103, in _multicall\n    res = hook_impl.function(*args)\n          ^^^^^^^^^^^^^^^^^^^^^^^^^\n  File \"/opt/hostedtoolcache/Python/3.12.6/x64/lib/python3.12/site-packages/_pytest/fixtures.py\", line 1140, in pytest_fixture_setup\n    result = call_fixture_func(fixturefunc, request, kwargs)\n             ^^^^^^^^^^^^^^^^^^^^^^^^^^^^^^^^^^^^^^^^^^^^^^^\n  File \"/opt/hostedtoolcache/Python/3.12.6/x64/lib/python3.12/site-packages/_pytest/fixtures.py\", line 898, in call_fixture_func\n    fixture_result = fixturefunc(**kwargs)\n                     ^^^^^^^^^^^^^^^^^^^^^\n  File \"/home/runner/work/qa-website/qa-website/conftest.py\", line 160, in class_create_session\n    return prepare_user_session(auth_data=cfg.PREMIUM_USER)\n           ^^^^^^^^^^^^^^^^^^^^^^^^^^^^^^^^^^^^^^^^^^^^^^^^\n  File \"/home/runner/work/qa-website/qa-website/modules/Utils.py\", line 56, in prepare_user_session\n    res = AuthApi(auth_data=auth_data)\n          ^^^^^^^^^^^^^^^^^^^^^^^^^^^^\n  File \"/home/runner/work/qa-website/qa-website/src/api/base_api.py\", line 22, in __init__\n    self._login(auth_data)\n  File \"/home/runner/work/qa-website/qa-website/src/api/base_api.py\", line 30, in _login\n    raise e\n  File \"/home/runner/work/qa-website/qa-website/src/api/base_api.py\", line 27, in _login\n    response.raise_for_status()\n  File \"/opt/hostedtoolcache/Python/3.12.6/x64/lib/python3.12/site-packages/requests/models.py\", line 1021, in raise_for_status\n    raise HTTPError(http_error_msg, response=self)\n","steps":[],"attachments":[],"parameters":[],"shouldDisplayMessage":true,"stepsCount":0,"attachmentsCount":0,"hasContent":true},{"name":"class_create_session","time":{"start":1726945027240,"stop":1726945028037,"duration":797},"status":"broken","statusMessage":"requests.exceptions.HTTPError: 401 Client Error: Unauthorized for url: https://dev.api.darkbot.io/auth/login\n","statusTrace":"  File \"/opt/hostedtoolcache/Python/3.12.6/x64/lib/python3.12/site-packages/pluggy/_callers.py\", line 167, in _multicall\n    teardown.throw(outcome._exception)\n  File \"/opt/hostedtoolcache/Python/3.12.6/x64/lib/python3.12/site-packages/_pytest/setuponly.py\", line 36, in pytest_fixture_setup\n    return (yield)\n            ^^^^^\n  File \"/opt/hostedtoolcache/Python/3.12.6/x64/lib/python3.12/site-packages/pluggy/_callers.py\", line 103, in _multicall\n    res = hook_impl.function(*args)\n          ^^^^^^^^^^^^^^^^^^^^^^^^^\n  File \"/opt/hostedtoolcache/Python/3.12.6/x64/lib/python3.12/site-packages/_pytest/fixtures.py\", line 1140, in pytest_fixture_setup\n    result = call_fixture_func(fixturefunc, request, kwargs)\n             ^^^^^^^^^^^^^^^^^^^^^^^^^^^^^^^^^^^^^^^^^^^^^^^\n  File \"/opt/hostedtoolcache/Python/3.12.6/x64/lib/python3.12/site-packages/_pytest/fixtures.py\", line 898, in call_fixture_func\n    fixture_result = fixturefunc(**kwargs)\n                     ^^^^^^^^^^^^^^^^^^^^^\n  File \"/home/runner/work/qa-website/qa-website/conftest.py\", line 160, in class_create_session\n    return prepare_user_session(auth_data=cfg.PREMIUM_USER)\n           ^^^^^^^^^^^^^^^^^^^^^^^^^^^^^^^^^^^^^^^^^^^^^^^^\n  File \"/home/runner/work/qa-website/qa-website/modules/Utils.py\", line 56, in prepare_user_session\n    res = AuthApi(auth_data=auth_data)\n          ^^^^^^^^^^^^^^^^^^^^^^^^^^^^\n  File \"/home/runner/work/qa-website/qa-website/src/api/base_api.py\", line 22, in __init__\n    self._login(auth_data)\n  File \"/home/runner/work/qa-website/qa-website/src/api/base_api.py\", line 30, in _login\n    raise e\n  File \"/home/runner/work/qa-website/qa-website/src/api/base_api.py\", line 27, in _login\n    response.raise_for_status()\n  File \"/opt/hostedtoolcache/Python/3.12.6/x64/lib/python3.12/site-packages/requests/models.py\", line 1021, in raise_for_status\n    raise HTTPError(http_error_msg, response=self)\n","steps":[],"attachments":[],"parameters":[],"shouldDisplayMessage":true,"stepsCount":0,"attachmentsCount":0,"hasContent":true},{"name":"class_create_session","time":{"start":1726945028089,"stop":1726945028747,"duration":658},"status":"broken","statusMessage":"requests.exceptions.HTTPError: 401 Client Error: Unauthorized for url: https://dev.api.darkbot.io/auth/login\n","statusTrace":"  File \"/opt/hostedtoolcache/Python/3.12.6/x64/lib/python3.12/site-packages/pluggy/_callers.py\", line 167, in _multicall\n    teardown.throw(outcome._exception)\n  File \"/opt/hostedtoolcache/Python/3.12.6/x64/lib/python3.12/site-packages/_pytest/setuponly.py\", line 36, in pytest_fixture_setup\n    return (yield)\n            ^^^^^\n  File \"/opt/hostedtoolcache/Python/3.12.6/x64/lib/python3.12/site-packages/pluggy/_callers.py\", line 103, in _multicall\n    res = hook_impl.function(*args)\n          ^^^^^^^^^^^^^^^^^^^^^^^^^\n  File \"/opt/hostedtoolcache/Python/3.12.6/x64/lib/python3.12/site-packages/_pytest/fixtures.py\", line 1140, in pytest_fixture_setup\n    result = call_fixture_func(fixturefunc, request, kwargs)\n             ^^^^^^^^^^^^^^^^^^^^^^^^^^^^^^^^^^^^^^^^^^^^^^^\n  File \"/opt/hostedtoolcache/Python/3.12.6/x64/lib/python3.12/site-packages/_pytest/fixtures.py\", line 898, in call_fixture_func\n    fixture_result = fixturefunc(**kwargs)\n                     ^^^^^^^^^^^^^^^^^^^^^\n  File \"/home/runner/work/qa-website/qa-website/conftest.py\", line 160, in class_create_session\n    return prepare_user_session(auth_data=cfg.PREMIUM_USER)\n           ^^^^^^^^^^^^^^^^^^^^^^^^^^^^^^^^^^^^^^^^^^^^^^^^\n  File \"/home/runner/work/qa-website/qa-website/modules/Utils.py\", line 56, in prepare_user_session\n    res = AuthApi(auth_data=auth_data)\n          ^^^^^^^^^^^^^^^^^^^^^^^^^^^^\n  File \"/home/runner/work/qa-website/qa-website/src/api/base_api.py\", line 22, in __init__\n    self._login(auth_data)\n  File \"/home/runner/work/qa-website/qa-website/src/api/base_api.py\", line 30, in _login\n    raise e\n  File \"/home/runner/work/qa-website/qa-website/src/api/base_api.py\", line 27, in _login\n    response.raise_for_status()\n  File \"/opt/hostedtoolcache/Python/3.12.6/x64/lib/python3.12/site-packages/requests/models.py\", line 1021, in raise_for_status\n    raise HTTPError(http_error_msg, response=self)\n","steps":[],"attachments":[],"parameters":[],"shouldDisplayMessage":true,"stepsCount":0,"attachmentsCount":0,"hasContent":true},{"name":"class_create_session","time":{"start":1726945028794,"stop":1726945029441,"duration":647},"status":"broken","statusMessage":"requests.exceptions.HTTPError: 401 Client Error: Unauthorized for url: https://dev.api.darkbot.io/auth/login\n","statusTrace":"  File \"/opt/hostedtoolcache/Python/3.12.6/x64/lib/python3.12/site-packages/pluggy/_callers.py\", line 167, in _multicall\n    teardown.throw(outcome._exception)\n  File \"/opt/hostedtoolcache/Python/3.12.6/x64/lib/python3.12/site-packages/_pytest/setuponly.py\", line 36, in pytest_fixture_setup\n    return (yield)\n            ^^^^^\n  File \"/opt/hostedtoolcache/Python/3.12.6/x64/lib/python3.12/site-packages/pluggy/_callers.py\", line 103, in _multicall\n    res = hook_impl.function(*args)\n          ^^^^^^^^^^^^^^^^^^^^^^^^^\n  File \"/opt/hostedtoolcache/Python/3.12.6/x64/lib/python3.12/site-packages/_pytest/fixtures.py\", line 1140, in pytest_fixture_setup\n    result = call_fixture_func(fixturefunc, request, kwargs)\n             ^^^^^^^^^^^^^^^^^^^^^^^^^^^^^^^^^^^^^^^^^^^^^^^\n  File \"/opt/hostedtoolcache/Python/3.12.6/x64/lib/python3.12/site-packages/_pytest/fixtures.py\", line 898, in call_fixture_func\n    fixture_result = fixturefunc(**kwargs)\n                     ^^^^^^^^^^^^^^^^^^^^^\n  File \"/home/runner/work/qa-website/qa-website/conftest.py\", line 160, in class_create_session\n    return prepare_user_session(auth_data=cfg.PREMIUM_USER)\n           ^^^^^^^^^^^^^^^^^^^^^^^^^^^^^^^^^^^^^^^^^^^^^^^^\n  File \"/home/runner/work/qa-website/qa-website/modules/Utils.py\", line 56, in prepare_user_session\n    res = AuthApi(auth_data=auth_data)\n          ^^^^^^^^^^^^^^^^^^^^^^^^^^^^\n  File \"/home/runner/work/qa-website/qa-website/src/api/base_api.py\", line 22, in __init__\n    self._login(auth_data)\n  File \"/home/runner/work/qa-website/qa-website/src/api/base_api.py\", line 30, in _login\n    raise e\n  File \"/home/runner/work/qa-website/qa-website/src/api/base_api.py\", line 27, in _login\n    response.raise_for_status()\n  File \"/opt/hostedtoolcache/Python/3.12.6/x64/lib/python3.12/site-packages/requests/models.py\", line 1021, in raise_for_status\n    raise HTTPError(http_error_msg, response=self)\n","steps":[],"attachments":[],"parameters":[],"shouldDisplayMessage":true,"stepsCount":0,"attachmentsCount":0,"hasContent":true},{"name":"class_create_session","time":{"start":1726945029491,"stop":1726945030149,"duration":658},"status":"broken","statusMessage":"requests.exceptions.HTTPError: 401 Client Error: Unauthorized for url: https://dev.api.darkbot.io/auth/login\n","statusTrace":"  File \"/opt/hostedtoolcache/Python/3.12.6/x64/lib/python3.12/site-packages/pluggy/_callers.py\", line 167, in _multicall\n    teardown.throw(outcome._exception)\n  File \"/opt/hostedtoolcache/Python/3.12.6/x64/lib/python3.12/site-packages/_pytest/setuponly.py\", line 36, in pytest_fixture_setup\n    return (yield)\n            ^^^^^\n  File \"/opt/hostedtoolcache/Python/3.12.6/x64/lib/python3.12/site-packages/pluggy/_callers.py\", line 103, in _multicall\n    res = hook_impl.function(*args)\n          ^^^^^^^^^^^^^^^^^^^^^^^^^\n  File \"/opt/hostedtoolcache/Python/3.12.6/x64/lib/python3.12/site-packages/_pytest/fixtures.py\", line 1140, in pytest_fixture_setup\n    result = call_fixture_func(fixturefunc, request, kwargs)\n             ^^^^^^^^^^^^^^^^^^^^^^^^^^^^^^^^^^^^^^^^^^^^^^^\n  File \"/opt/hostedtoolcache/Python/3.12.6/x64/lib/python3.12/site-packages/_pytest/fixtures.py\", line 898, in call_fixture_func\n    fixture_result = fixturefunc(**kwargs)\n                     ^^^^^^^^^^^^^^^^^^^^^\n  File \"/home/runner/work/qa-website/qa-website/conftest.py\", line 160, in class_create_session\n    return prepare_user_session(auth_data=cfg.PREMIUM_USER)\n           ^^^^^^^^^^^^^^^^^^^^^^^^^^^^^^^^^^^^^^^^^^^^^^^^\n  File \"/home/runner/work/qa-website/qa-website/modules/Utils.py\", line 56, in prepare_user_session\n    res = AuthApi(auth_data=auth_data)\n          ^^^^^^^^^^^^^^^^^^^^^^^^^^^^\n  File \"/home/runner/work/qa-website/qa-website/src/api/base_api.py\", line 22, in __init__\n    self._login(auth_data)\n  File \"/home/runner/work/qa-website/qa-website/src/api/base_api.py\", line 30, in _login\n    raise e\n  File \"/home/runner/work/qa-website/qa-website/src/api/base_api.py\", line 27, in _login\n    response.raise_for_status()\n  File \"/opt/hostedtoolcache/Python/3.12.6/x64/lib/python3.12/site-packages/requests/models.py\", line 1021, in raise_for_status\n    raise HTTPError(http_error_msg, response=self)\n","steps":[],"attachments":[],"parameters":[],"shouldDisplayMessage":true,"stepsCount":0,"attachmentsCount":0,"hasContent":true},{"name":"class_create_session","time":{"start":1726945030197,"stop":1726945030846,"duration":649},"status":"broken","statusMessage":"requests.exceptions.HTTPError: 401 Client Error: Unauthorized for url: https://dev.api.darkbot.io/auth/login\n","statusTrace":"  File \"/opt/hostedtoolcache/Python/3.12.6/x64/lib/python3.12/site-packages/pluggy/_callers.py\", line 167, in _multicall\n    teardown.throw(outcome._exception)\n  File \"/opt/hostedtoolcache/Python/3.12.6/x64/lib/python3.12/site-packages/_pytest/setuponly.py\", line 36, in pytest_fixture_setup\n    return (yield)\n            ^^^^^\n  File \"/opt/hostedtoolcache/Python/3.12.6/x64/lib/python3.12/site-packages/pluggy/_callers.py\", line 103, in _multicall\n    res = hook_impl.function(*args)\n          ^^^^^^^^^^^^^^^^^^^^^^^^^\n  File \"/opt/hostedtoolcache/Python/3.12.6/x64/lib/python3.12/site-packages/_pytest/fixtures.py\", line 1140, in pytest_fixture_setup\n    result = call_fixture_func(fixturefunc, request, kwargs)\n             ^^^^^^^^^^^^^^^^^^^^^^^^^^^^^^^^^^^^^^^^^^^^^^^\n  File \"/opt/hostedtoolcache/Python/3.12.6/x64/lib/python3.12/site-packages/_pytest/fixtures.py\", line 898, in call_fixture_func\n    fixture_result = fixturefunc(**kwargs)\n                     ^^^^^^^^^^^^^^^^^^^^^\n  File \"/home/runner/work/qa-website/qa-website/conftest.py\", line 160, in class_create_session\n    return prepare_user_session(auth_data=cfg.PREMIUM_USER)\n           ^^^^^^^^^^^^^^^^^^^^^^^^^^^^^^^^^^^^^^^^^^^^^^^^\n  File \"/home/runner/work/qa-website/qa-website/modules/Utils.py\", line 56, in prepare_user_session\n    res = AuthApi(auth_data=auth_data)\n          ^^^^^^^^^^^^^^^^^^^^^^^^^^^^\n  File \"/home/runner/work/qa-website/qa-website/src/api/base_api.py\", line 22, in __init__\n    self._login(auth_data)\n  File \"/home/runner/work/qa-website/qa-website/src/api/base_api.py\", line 30, in _login\n    raise e\n  File \"/home/runner/work/qa-website/qa-website/src/api/base_api.py\", line 27, in _login\n    response.raise_for_status()\n  File \"/opt/hostedtoolcache/Python/3.12.6/x64/lib/python3.12/site-packages/requests/models.py\", line 1021, in raise_for_status\n    raise HTTPError(http_error_msg, response=self)\n","steps":[],"attachments":[],"parameters":[],"shouldDisplayMessage":true,"stepsCount":0,"attachmentsCount":0,"hasContent":true},{"name":"class_create_session","time":{"start":1726945030900,"stop":1726945031562,"duration":662},"status":"broken","statusMessage":"requests.exceptions.HTTPError: 401 Client Error: Unauthorized for url: https://dev.api.darkbot.io/auth/login\n","statusTrace":"  File \"/opt/hostedtoolcache/Python/3.12.6/x64/lib/python3.12/site-packages/pluggy/_callers.py\", line 167, in _multicall\n    teardown.throw(outcome._exception)\n  File \"/opt/hostedtoolcache/Python/3.12.6/x64/lib/python3.12/site-packages/_pytest/setuponly.py\", line 36, in pytest_fixture_setup\n    return (yield)\n            ^^^^^\n  File \"/opt/hostedtoolcache/Python/3.12.6/x64/lib/python3.12/site-packages/pluggy/_callers.py\", line 103, in _multicall\n    res = hook_impl.function(*args)\n          ^^^^^^^^^^^^^^^^^^^^^^^^^\n  File \"/opt/hostedtoolcache/Python/3.12.6/x64/lib/python3.12/site-packages/_pytest/fixtures.py\", line 1140, in pytest_fixture_setup\n    result = call_fixture_func(fixturefunc, request, kwargs)\n             ^^^^^^^^^^^^^^^^^^^^^^^^^^^^^^^^^^^^^^^^^^^^^^^\n  File \"/opt/hostedtoolcache/Python/3.12.6/x64/lib/python3.12/site-packages/_pytest/fixtures.py\", line 898, in call_fixture_func\n    fixture_result = fixturefunc(**kwargs)\n                     ^^^^^^^^^^^^^^^^^^^^^\n  File \"/home/runner/work/qa-website/qa-website/conftest.py\", line 160, in class_create_session\n    return prepare_user_session(auth_data=cfg.PREMIUM_USER)\n           ^^^^^^^^^^^^^^^^^^^^^^^^^^^^^^^^^^^^^^^^^^^^^^^^\n  File \"/home/runner/work/qa-website/qa-website/modules/Utils.py\", line 56, in prepare_user_session\n    res = AuthApi(auth_data=auth_data)\n          ^^^^^^^^^^^^^^^^^^^^^^^^^^^^\n  File \"/home/runner/work/qa-website/qa-website/src/api/base_api.py\", line 22, in __init__\n    self._login(auth_data)\n  File \"/home/runner/work/qa-website/qa-website/src/api/base_api.py\", line 30, in _login\n    raise e\n  File \"/home/runner/work/qa-website/qa-website/src/api/base_api.py\", line 27, in _login\n    response.raise_for_status()\n  File \"/opt/hostedtoolcache/Python/3.12.6/x64/lib/python3.12/site-packages/requests/models.py\", line 1021, in raise_for_status\n    raise HTTPError(http_error_msg, response=self)\n","steps":[],"attachments":[],"parameters":[],"shouldDisplayMessage":true,"stepsCount":0,"attachmentsCount":0,"hasContent":true},{"name":"class_create_session","time":{"start":1726945031610,"stop":1726945032277,"duration":667},"status":"broken","statusMessage":"requests.exceptions.HTTPError: 401 Client Error: Unauthorized for url: https://dev.api.darkbot.io/auth/login\n","statusTrace":"  File \"/opt/hostedtoolcache/Python/3.12.6/x64/lib/python3.12/site-packages/pluggy/_callers.py\", line 167, in _multicall\n    teardown.throw(outcome._exception)\n  File \"/opt/hostedtoolcache/Python/3.12.6/x64/lib/python3.12/site-packages/_pytest/setuponly.py\", line 36, in pytest_fixture_setup\n    return (yield)\n            ^^^^^\n  File \"/opt/hostedtoolcache/Python/3.12.6/x64/lib/python3.12/site-packages/pluggy/_callers.py\", line 103, in _multicall\n    res = hook_impl.function(*args)\n          ^^^^^^^^^^^^^^^^^^^^^^^^^\n  File \"/opt/hostedtoolcache/Python/3.12.6/x64/lib/python3.12/site-packages/_pytest/fixtures.py\", line 1140, in pytest_fixture_setup\n    result = call_fixture_func(fixturefunc, request, kwargs)\n             ^^^^^^^^^^^^^^^^^^^^^^^^^^^^^^^^^^^^^^^^^^^^^^^\n  File \"/opt/hostedtoolcache/Python/3.12.6/x64/lib/python3.12/site-packages/_pytest/fixtures.py\", line 898, in call_fixture_func\n    fixture_result = fixturefunc(**kwargs)\n                     ^^^^^^^^^^^^^^^^^^^^^\n  File \"/home/runner/work/qa-website/qa-website/conftest.py\", line 160, in class_create_session\n    return prepare_user_session(auth_data=cfg.PREMIUM_USER)\n           ^^^^^^^^^^^^^^^^^^^^^^^^^^^^^^^^^^^^^^^^^^^^^^^^\n  File \"/home/runner/work/qa-website/qa-website/modules/Utils.py\", line 56, in prepare_user_session\n    res = AuthApi(auth_data=auth_data)\n          ^^^^^^^^^^^^^^^^^^^^^^^^^^^^\n  File \"/home/runner/work/qa-website/qa-website/src/api/base_api.py\", line 22, in __init__\n    self._login(auth_data)\n  File \"/home/runner/work/qa-website/qa-website/src/api/base_api.py\", line 30, in _login\n    raise e\n  File \"/home/runner/work/qa-website/qa-website/src/api/base_api.py\", line 27, in _login\n    response.raise_for_status()\n  File \"/opt/hostedtoolcache/Python/3.12.6/x64/lib/python3.12/site-packages/requests/models.py\", line 1021, in raise_for_status\n    raise HTTPError(http_error_msg, response=self)\n","steps":[],"attachments":[],"parameters":[],"shouldDisplayMessage":true,"stepsCount":0,"attachmentsCount":0,"hasContent":true}],"testStage":{"descriptionHtml":"<h4 style=\"margin: -10px 0 5px;\"><span style=\"margin: 9px 4px 9px 0; cursor: pointer\" class=\"fa fa-files-o\" data-copy=\"test_load_pages_with_title[billing-Billing-//h1]\"></span>test_load_pages_with_title[billing-Billing-//h1]</h4>\n    Collected at <span class=\"label label_status_passed\">2024-09-21 18:54</span><br><br>","status":"broken","statusMessage":"requests.exceptions.HTTPError: 401 Client Error: Unauthorized for url: https://dev.api.darkbot.io/auth/login","statusTrace":"@pytest.fixture(scope=\"class\")\n    def class_create_session():\n        from modules.Utils import prepare_user_session\n>       return prepare_user_session(auth_data=cfg.PREMIUM_USER)\n\nprepare_user_session = <function prepare_user_session at 0x7f726cdf65c0>\n\nconftest.py:160: \n_ _ _ _ _ _ _ _ _ _ _ _ _ _ _ _ _ _ _ _ _ _ _ _ _ _ _ _ _ _ _ _ _ _ _ _ _ _ _ _ \nmodules/Utils.py:56: in prepare_user_session\n    res = AuthApi(auth_data=auth_data)\n        auth_data  = {'password': 'darkbot123', 'token': 'token', 'username': 'premium@darkbot.io'}\nsrc/api/base_api.py:22: in __init__\n    self._login(auth_data)\n        auth_data  = {'password': 'darkbot123', 'token': 'token', 'username': 'premium@darkbot.io'}\n        jwt_token  = None\n        lang       = 'en'\n        self       = <src.api.auth.register_api.AuthApi object at 0x7f7260161820>\nsrc/api/base_api.py:30: in _login\n    raise e\n        auth_data  = {'password': 'darkbot123', 'token': 'token', 'username': 'premium@darkbot.io'}\n        response   = <Response [401]>\n        self       = <src.api.auth.register_api.AuthApi object at 0x7f7260161820>\nsrc/api/base_api.py:27: in _login\n    response.raise_for_status()\n        auth_data  = {'password': 'darkbot123', 'token': 'token', 'username': 'premium@darkbot.io'}\n        response   = <Response [401]>\n        self       = <src.api.auth.register_api.AuthApi object at 0x7f7260161820>\n_ _ _ _ _ _ _ _ _ _ _ _ _ _ _ _ _ _ _ _ _ _ _ _ _ _ _ _ _ _ _ _ _ _ _ _ _ _ _ _ \n\nself = <Response [401]>\n\n    def raise_for_status(self):\n        \"\"\"Raises :class:`HTTPError`, if one occurred.\"\"\"\n    \n        http_error_msg = \"\"\n        if isinstance(self.reason, bytes):\n            # We attempt to decode utf-8 first because some servers\n            # choose to localize their reason strings. If the string\n            # isn't utf-8, we fall back to iso-8859-1 for all other\n            # encodings. (See PR #3538)\n            try:\n                reason = self.reason.decode(\"utf-8\")\n            except UnicodeDecodeError:\n                reason = self.reason.decode(\"iso-8859-1\")\n        else:\n            reason = self.reason\n    \n        if 400 <= self.status_code < 500:\n            http_error_msg = (\n                f\"{self.status_code} Client Error: {reason} for url: {self.url}\"\n            )\n    \n        elif 500 <= self.status_code < 600:\n            http_error_msg = (\n                f\"{self.status_code} Server Error: {reason} for url: {self.url}\"\n            )\n    \n        if http_error_msg:\n>           raise HTTPError(http_error_msg, response=self)\nE           requests.exceptions.HTTPError: 401 Client Error: Unauthorized for url: https://dev.api.darkbot.io/auth/login\n\nhttp_error_msg = '401 Client Error: Unauthorized for url: https://dev.api.darkbot.io/auth/login'\nreason     = 'Unauthorized'\nself       = <Response [401]>\n\n/opt/hostedtoolcache/Python/3.12.6/x64/lib/python3.12/site-packages/requests/models.py:1021: HTTPError","steps":[],"attachments":[{"uid":"a185a1ac2707346","name":"log","source":"a185a1ac2707346.txt","type":"text/plain","size":233}],"parameters":[],"shouldDisplayMessage":true,"stepsCount":0,"attachmentsCount":1,"hasContent":true},"afterStages":[],"labels":[{"name":"suite","value":"Pages load"},{"name":"parentSuite","value":"tests.performance"},{"name":"subSuite","value":"TestLoadPage"},{"name":"host","value":"fv-az1521-508"},{"name":"thread","value":"5413-MainThread"},{"name":"framework","value":"pytest"},{"name":"language","value":"cpython3"},{"name":"package","value":"tests.performance.test_load_page"},{"name":"resultFormat","value":"allure2"}],"parameters":[{"name":"loc","value":"'//h1'"},{"name":"slug","value":"'billing'"},{"name":"title","value":"'Billing'"}],"links":[],"hidden":false,"retry":false,"extra":{"severity":"normal","retries":[{"uid":"61f8f944bfedf17d","status":"broken","statusDetails":"requests.exceptions.HTTPError: 401 Client Error: Unauthorized for url: https://dev.api.darkbot.io/auth/login","time":{"start":1726945030174,"stop":1726945030174,"duration":0}}],"categories":[{"name":"Test defects","matchedStatuses":[],"flaky":false}],"history":{"statistic":{"failed":0,"broken":2,"skipped":0,"passed":3,"unknown":0,"total":5},"items":[{"uid":"19b21a3970972345","reportUrl":"https://darkbot-io.github.io/qa-website/531//#testresult/19b21a3970972345","status":"broken","statusDetails":"requests.exceptions.HTTPError: 401 Client Error: Unauthorized for url: https://dev.api.darkbot.io/auth/login","time":{"start":1726943356646,"stop":1726943363723,"duration":7077}},{"uid":"5cda572736819bbe","reportUrl":"https://darkbot-io.github.io/qa-website/529//#testresult/5cda572736819bbe","status":"passed","time":{"start":1726772862959,"stop":1726772877486,"duration":14527}},{"uid":"58e600b489dd382b","reportUrl":"https://darkbot-io.github.io/qa-website/528//#testresult/58e600b489dd382b","status":"passed","time":{"start":1726334477146,"stop":1726334489917,"duration":12771}},{"uid":"678ef8387f0f334d","reportUrl":"https://darkbot-io.github.io/qa-website/527//#testresult/678ef8387f0f334d","status":"passed","time":{"start":1725729638933,"stop":1725729651817,"duration":12884}}]},"tags":[]},"source":"9e26c66a98dc3f03.json","parameterValues":["'//h1'","'billing'","'Billing'"]}